INFO:     Started server process [25245]
INFO:     Waiting for application startup.
INFO:     Application startup complete.
INFO:     Uvicorn running on http://127.0.0.1:443 (Press CTRL+C to quit)
Connected to the database!
INFO:     127.0.0.1:44056 - "GET /api/pull-static-data HTTP/1.1" 500 Internal Server Error
ERROR:    Exception in ASGI application
Traceback (most recent call last):
  File "/usr/local/lib/python3.10/dist-packages/uvicorn/protocols/http/h11_impl.py", line 408, in run_asgi
    result = await app(  # type: ignore[func-returns-value]
  File "/usr/local/lib/python3.10/dist-packages/uvicorn/middleware/proxy_headers.py", line 84, in __call__
    return await self.app(scope, receive, send)
  File "/usr/local/lib/python3.10/dist-packages/fastapi/applications.py", line 1106, in __call__
    await super().__call__(scope, receive, send)
  File "/usr/local/lib/python3.10/dist-packages/starlette/applications.py", line 122, in __call__
    await self.middleware_stack(scope, receive, send)
  File "/usr/local/lib/python3.10/dist-packages/starlette/middleware/errors.py", line 184, in __call__
    raise exc
  File "/usr/local/lib/python3.10/dist-packages/starlette/middleware/errors.py", line 162, in __call__
    await self.app(scope, receive, _send)
  File "/usr/local/lib/python3.10/dist-packages/starlette/middleware/cors.py", line 83, in __call__
    await self.app(scope, receive, send)
  File "/usr/local/lib/python3.10/dist-packages/starlette/middleware/exceptions.py", line 79, in __call__
    raise exc
  File "/usr/local/lib/python3.10/dist-packages/starlette/middleware/exceptions.py", line 68, in __call__
    await self.app(scope, receive, sender)
  File "/usr/local/lib/python3.10/dist-packages/fastapi/middleware/asyncexitstack.py", line 20, in __call__
    raise e
  File "/usr/local/lib/python3.10/dist-packages/fastapi/middleware/asyncexitstack.py", line 17, in __call__
    await self.app(scope, receive, send)
  File "/usr/local/lib/python3.10/dist-packages/starlette/routing.py", line 718, in __call__
    await route.handle(scope, receive, send)
  File "/usr/local/lib/python3.10/dist-packages/starlette/routing.py", line 276, in handle
    await self.app(scope, receive, send)
  File "/usr/local/lib/python3.10/dist-packages/starlette/routing.py", line 66, in app
    response = await func(request)
  File "/usr/local/lib/python3.10/dist-packages/fastapi/routing.py", line 274, in app
    raw_response = await run_endpoint_function(
  File "/usr/local/lib/python3.10/dist-packages/fastapi/routing.py", line 193, in run_endpoint_function
    return await run_in_threadpool(dependant.call, **values)
  File "/usr/local/lib/python3.10/dist-packages/starlette/concurrency.py", line 41, in run_in_threadpool
    return await anyio.to_thread.run_sync(func, *args)
  File "/usr/local/lib/python3.10/dist-packages/anyio/to_thread.py", line 33, in run_sync
    return await get_asynclib().run_sync_in_worker_thread(
  File "/usr/local/lib/python3.10/dist-packages/anyio/_backends/_asyncio.py", line 877, in run_sync_in_worker_thread
    return await future
  File "/usr/local/lib/python3.10/dist-packages/anyio/_backends/_asyncio.py", line 807, in run
    result = context.run(func, *args)
  File "/root/KHT_Team/Src/api_provider2.py", line 27, in pull_static_data
    geojson_data = postgreSQL.get_table("village")
  File "/root/KHT_Team/Src/postgreSQL.py", line 42, in get_table
    geojson_result = query_to_geojson(cursor, query)
  File "/root/KHT_Team/Src/postgreSQL.py", line 31, in query_to_geojson
    feature = geojson.Feature(geometry=geometry, properties=properties)
  File "/usr/local/lib/python3.10/dist-packages/geojson/feature.py", line 24, in __init__
    self["geometry"] = (self.to_instance(geometry, strict=True)
  File "/usr/local/lib/python3.10/dist-packages/geojson/base.py", line 113, in to_instance
    instance = geojson_factory(**d)
  File "/usr/local/lib/python3.10/dist-packages/geojson/geometry.py", line 29, in __init__
    self["coordinates"] = self.clean_coordinates(
  File "/usr/local/lib/python3.10/dist-packages/geojson/geometry.py", line 53, in clean_coordinates
    raise ValueError("%r is not a JSON compliant number" % coord)
ValueError: None is not a JSON compliant number
INFO:     127.0.0.1:44072 - "GET /api/pull-static-data HTTP/1.1" 500 Internal Server Error
ERROR:    Exception in ASGI application
Traceback (most recent call last):
  File "/usr/local/lib/python3.10/dist-packages/uvicorn/protocols/http/h11_impl.py", line 408, in run_asgi
    result = await app(  # type: ignore[func-returns-value]
  File "/usr/local/lib/python3.10/dist-packages/uvicorn/middleware/proxy_headers.py", line 84, in __call__
    return await self.app(scope, receive, send)
  File "/usr/local/lib/python3.10/dist-packages/fastapi/applications.py", line 1106, in __call__
    await super().__call__(scope, receive, send)
  File "/usr/local/lib/python3.10/dist-packages/starlette/applications.py", line 122, in __call__
    await self.middleware_stack(scope, receive, send)
  File "/usr/local/lib/python3.10/dist-packages/starlette/middleware/errors.py", line 184, in __call__
    raise exc
  File "/usr/local/lib/python3.10/dist-packages/starlette/middleware/errors.py", line 162, in __call__
    await self.app(scope, receive, _send)
  File "/usr/local/lib/python3.10/dist-packages/starlette/middleware/cors.py", line 83, in __call__
    await self.app(scope, receive, send)
  File "/usr/local/lib/python3.10/dist-packages/starlette/middleware/exceptions.py", line 79, in __call__
    raise exc
  File "/usr/local/lib/python3.10/dist-packages/starlette/middleware/exceptions.py", line 68, in __call__
    await self.app(scope, receive, sender)
  File "/usr/local/lib/python3.10/dist-packages/fastapi/middleware/asyncexitstack.py", line 20, in __call__
    raise e
  File "/usr/local/lib/python3.10/dist-packages/fastapi/middleware/asyncexitstack.py", line 17, in __call__
    await self.app(scope, receive, send)
  File "/usr/local/lib/python3.10/dist-packages/starlette/routing.py", line 718, in __call__
    await route.handle(scope, receive, send)
  File "/usr/local/lib/python3.10/dist-packages/starlette/routing.py", line 276, in handle
    await self.app(scope, receive, send)
  File "/usr/local/lib/python3.10/dist-packages/starlette/routing.py", line 66, in app
    response = await func(request)
  File "/usr/local/lib/python3.10/dist-packages/fastapi/routing.py", line 274, in app
    raw_response = await run_endpoint_function(
  File "/usr/local/lib/python3.10/dist-packages/fastapi/routing.py", line 193, in run_endpoint_function
    return await run_in_threadpool(dependant.call, **values)
  File "/usr/local/lib/python3.10/dist-packages/starlette/concurrency.py", line 41, in run_in_threadpool
    return await anyio.to_thread.run_sync(func, *args)
  File "/usr/local/lib/python3.10/dist-packages/anyio/to_thread.py", line 33, in run_sync
    return await get_asynclib().run_sync_in_worker_thread(
  File "/usr/local/lib/python3.10/dist-packages/anyio/_backends/_asyncio.py", line 877, in run_sync_in_worker_thread
    return await future
  File "/usr/local/lib/python3.10/dist-packages/anyio/_backends/_asyncio.py", line 807, in run
    result = context.run(func, *args)
  File "/root/KHT_Team/Src/api_provider2.py", line 27, in pull_static_data
    geojson_data = postgreSQL.get_table("village")
  File "/root/KHT_Team/Src/postgreSQL.py", line 42, in get_table
    geojson_result = query_to_geojson(cursor, query)
  File "/root/KHT_Team/Src/postgreSQL.py", line 31, in query_to_geojson
    feature = geojson.Feature(geometry=geometry, properties=properties)
  File "/usr/local/lib/python3.10/dist-packages/geojson/feature.py", line 24, in __init__
    self["geometry"] = (self.to_instance(geometry, strict=True)
  File "/usr/local/lib/python3.10/dist-packages/geojson/base.py", line 113, in to_instance
    instance = geojson_factory(**d)
  File "/usr/local/lib/python3.10/dist-packages/geojson/geometry.py", line 29, in __init__
    self["coordinates"] = self.clean_coordinates(
  File "/usr/local/lib/python3.10/dist-packages/geojson/geometry.py", line 53, in clean_coordinates
    raise ValueError("%r is not a JSON compliant number" % coord)
ValueError: None is not a JSON compliant number
INFO:     127.0.0.1:44086 - "GET /api/pull-static-data HTTP/1.1" 500 Internal Server Error
ERROR:    Exception in ASGI application
Traceback (most recent call last):
  File "/usr/local/lib/python3.10/dist-packages/uvicorn/protocols/http/h11_impl.py", line 408, in run_asgi
    result = await app(  # type: ignore[func-returns-value]
  File "/usr/local/lib/python3.10/dist-packages/uvicorn/middleware/proxy_headers.py", line 84, in __call__
    return await self.app(scope, receive, send)
  File "/usr/local/lib/python3.10/dist-packages/fastapi/applications.py", line 1106, in __call__
    await super().__call__(scope, receive, send)
  File "/usr/local/lib/python3.10/dist-packages/starlette/applications.py", line 122, in __call__
    await self.middleware_stack(scope, receive, send)
  File "/usr/local/lib/python3.10/dist-packages/starlette/middleware/errors.py", line 184, in __call__
    raise exc
  File "/usr/local/lib/python3.10/dist-packages/starlette/middleware/errors.py", line 162, in __call__
    await self.app(scope, receive, _send)
  File "/usr/local/lib/python3.10/dist-packages/starlette/middleware/cors.py", line 83, in __call__
    await self.app(scope, receive, send)
  File "/usr/local/lib/python3.10/dist-packages/starlette/middleware/exceptions.py", line 79, in __call__
    raise exc
  File "/usr/local/lib/python3.10/dist-packages/starlette/middleware/exceptions.py", line 68, in __call__
    await self.app(scope, receive, sender)
  File "/usr/local/lib/python3.10/dist-packages/fastapi/middleware/asyncexitstack.py", line 20, in __call__
    raise e
  File "/usr/local/lib/python3.10/dist-packages/fastapi/middleware/asyncexitstack.py", line 17, in __call__
    await self.app(scope, receive, send)
  File "/usr/local/lib/python3.10/dist-packages/starlette/routing.py", line 718, in __call__
    await route.handle(scope, receive, send)
  File "/usr/local/lib/python3.10/dist-packages/starlette/routing.py", line 276, in handle
    await self.app(scope, receive, send)
  File "/usr/local/lib/python3.10/dist-packages/starlette/routing.py", line 66, in app
    response = await func(request)
  File "/usr/local/lib/python3.10/dist-packages/fastapi/routing.py", line 274, in app
    raw_response = await run_endpoint_function(
  File "/usr/local/lib/python3.10/dist-packages/fastapi/routing.py", line 193, in run_endpoint_function
    return await run_in_threadpool(dependant.call, **values)
  File "/usr/local/lib/python3.10/dist-packages/starlette/concurrency.py", line 41, in run_in_threadpool
    return await anyio.to_thread.run_sync(func, *args)
  File "/usr/local/lib/python3.10/dist-packages/anyio/to_thread.py", line 33, in run_sync
    return await get_asynclib().run_sync_in_worker_thread(
  File "/usr/local/lib/python3.10/dist-packages/anyio/_backends/_asyncio.py", line 877, in run_sync_in_worker_thread
    return await future
  File "/usr/local/lib/python3.10/dist-packages/anyio/_backends/_asyncio.py", line 807, in run
    result = context.run(func, *args)
  File "/root/KHT_Team/Src/api_provider2.py", line 27, in pull_static_data
    geojson_data = postgreSQL.get_table("village")
  File "/root/KHT_Team/Src/postgreSQL.py", line 42, in get_table
    geojson_result = query_to_geojson(cursor, query)
  File "/root/KHT_Team/Src/postgreSQL.py", line 31, in query_to_geojson
    feature = geojson.Feature(geometry=geometry, properties=properties)
  File "/usr/local/lib/python3.10/dist-packages/geojson/feature.py", line 24, in __init__
    self["geometry"] = (self.to_instance(geometry, strict=True)
  File "/usr/local/lib/python3.10/dist-packages/geojson/base.py", line 113, in to_instance
    instance = geojson_factory(**d)
  File "/usr/local/lib/python3.10/dist-packages/geojson/geometry.py", line 29, in __init__
    self["coordinates"] = self.clean_coordinates(
  File "/usr/local/lib/python3.10/dist-packages/geojson/geometry.py", line 53, in clean_coordinates
    raise ValueError("%r is not a JSON compliant number" % coord)
ValueError: None is not a JSON compliant number
INFO:     127.0.0.1:59808 - "GET /api/pull-static-data HTTP/1.1" 500 Internal Server Error
ERROR:    Exception in ASGI application
Traceback (most recent call last):
  File "/usr/local/lib/python3.10/dist-packages/uvicorn/protocols/http/h11_impl.py", line 408, in run_asgi
    result = await app(  # type: ignore[func-returns-value]
  File "/usr/local/lib/python3.10/dist-packages/uvicorn/middleware/proxy_headers.py", line 84, in __call__
    return await self.app(scope, receive, send)
  File "/usr/local/lib/python3.10/dist-packages/fastapi/applications.py", line 1106, in __call__
    await super().__call__(scope, receive, send)
  File "/usr/local/lib/python3.10/dist-packages/starlette/applications.py", line 122, in __call__
    await self.middleware_stack(scope, receive, send)
  File "/usr/local/lib/python3.10/dist-packages/starlette/middleware/errors.py", line 184, in __call__
    raise exc
  File "/usr/local/lib/python3.10/dist-packages/starlette/middleware/errors.py", line 162, in __call__
    await self.app(scope, receive, _send)
  File "/usr/local/lib/python3.10/dist-packages/starlette/middleware/cors.py", line 83, in __call__
    await self.app(scope, receive, send)
  File "/usr/local/lib/python3.10/dist-packages/starlette/middleware/exceptions.py", line 79, in __call__
    raise exc
  File "/usr/local/lib/python3.10/dist-packages/starlette/middleware/exceptions.py", line 68, in __call__
    await self.app(scope, receive, sender)
  File "/usr/local/lib/python3.10/dist-packages/fastapi/middleware/asyncexitstack.py", line 20, in __call__
    raise e
  File "/usr/local/lib/python3.10/dist-packages/fastapi/middleware/asyncexitstack.py", line 17, in __call__
    await self.app(scope, receive, send)
  File "/usr/local/lib/python3.10/dist-packages/starlette/routing.py", line 718, in __call__
    await route.handle(scope, receive, send)
  File "/usr/local/lib/python3.10/dist-packages/starlette/routing.py", line 276, in handle
    await self.app(scope, receive, send)
  File "/usr/local/lib/python3.10/dist-packages/starlette/routing.py", line 66, in app
    response = await func(request)
  File "/usr/local/lib/python3.10/dist-packages/fastapi/routing.py", line 274, in app
    raw_response = await run_endpoint_function(
  File "/usr/local/lib/python3.10/dist-packages/fastapi/routing.py", line 193, in run_endpoint_function
    return await run_in_threadpool(dependant.call, **values)
  File "/usr/local/lib/python3.10/dist-packages/starlette/concurrency.py", line 41, in run_in_threadpool
    return await anyio.to_thread.run_sync(func, *args)
  File "/usr/local/lib/python3.10/dist-packages/anyio/to_thread.py", line 33, in run_sync
    return await get_asynclib().run_sync_in_worker_thread(
  File "/usr/local/lib/python3.10/dist-packages/anyio/_backends/_asyncio.py", line 877, in run_sync_in_worker_thread
    return await future
  File "/usr/local/lib/python3.10/dist-packages/anyio/_backends/_asyncio.py", line 807, in run
    result = context.run(func, *args)
  File "/root/KHT_Team/Src/api_provider2.py", line 27, in pull_static_data
    geojson_data = postgreSQL.get_table("village")
  File "/root/KHT_Team/Src/postgreSQL.py", line 42, in get_table
    geojson_result = query_to_geojson(cursor, query)
  File "/root/KHT_Team/Src/postgreSQL.py", line 31, in query_to_geojson
    feature = geojson.Feature(geometry=geometry, properties=properties)
  File "/usr/local/lib/python3.10/dist-packages/geojson/feature.py", line 24, in __init__
    self["geometry"] = (self.to_instance(geometry, strict=True)
  File "/usr/local/lib/python3.10/dist-packages/geojson/base.py", line 113, in to_instance
    instance = geojson_factory(**d)
  File "/usr/local/lib/python3.10/dist-packages/geojson/geometry.py", line 29, in __init__
    self["coordinates"] = self.clean_coordinates(
  File "/usr/local/lib/python3.10/dist-packages/geojson/geometry.py", line 53, in clean_coordinates
    raise ValueError("%r is not a JSON compliant number" % coord)
ValueError: None is not a JSON compliant number
INFO:     127.0.0.1:59798 - "GET /api/pull-static-data HTTP/1.1" 500 Internal Server Error
ERROR:    Exception in ASGI application
Traceback (most recent call last):
  File "/usr/local/lib/python3.10/dist-packages/uvicorn/protocols/http/h11_impl.py", line 408, in run_asgi
    result = await app(  # type: ignore[func-returns-value]
  File "/usr/local/lib/python3.10/dist-packages/uvicorn/middleware/proxy_headers.py", line 84, in __call__
    return await self.app(scope, receive, send)
  File "/usr/local/lib/python3.10/dist-packages/fastapi/applications.py", line 1106, in __call__
    await super().__call__(scope, receive, send)
  File "/usr/local/lib/python3.10/dist-packages/starlette/applications.py", line 122, in __call__
    await self.middleware_stack(scope, receive, send)
  File "/usr/local/lib/python3.10/dist-packages/starlette/middleware/errors.py", line 184, in __call__
    raise exc
  File "/usr/local/lib/python3.10/dist-packages/starlette/middleware/errors.py", line 162, in __call__
    await self.app(scope, receive, _send)
  File "/usr/local/lib/python3.10/dist-packages/starlette/middleware/cors.py", line 83, in __call__
    await self.app(scope, receive, send)
  File "/usr/local/lib/python3.10/dist-packages/starlette/middleware/exceptions.py", line 79, in __call__
    raise exc
  File "/usr/local/lib/python3.10/dist-packages/starlette/middleware/exceptions.py", line 68, in __call__
    await self.app(scope, receive, sender)
  File "/usr/local/lib/python3.10/dist-packages/fastapi/middleware/asyncexitstack.py", line 20, in __call__
    raise e
  File "/usr/local/lib/python3.10/dist-packages/fastapi/middleware/asyncexitstack.py", line 17, in __call__
    await self.app(scope, receive, send)
  File "/usr/local/lib/python3.10/dist-packages/starlette/routing.py", line 718, in __call__
    await route.handle(scope, receive, send)
  File "/usr/local/lib/python3.10/dist-packages/starlette/routing.py", line 276, in handle
    await self.app(scope, receive, send)
  File "/usr/local/lib/python3.10/dist-packages/starlette/routing.py", line 66, in app
    response = await func(request)
  File "/usr/local/lib/python3.10/dist-packages/fastapi/routing.py", line 274, in app
    raw_response = await run_endpoint_function(
  File "/usr/local/lib/python3.10/dist-packages/fastapi/routing.py", line 193, in run_endpoint_function
    return await run_in_threadpool(dependant.call, **values)
  File "/usr/local/lib/python3.10/dist-packages/starlette/concurrency.py", line 41, in run_in_threadpool
    return await anyio.to_thread.run_sync(func, *args)
  File "/usr/local/lib/python3.10/dist-packages/anyio/to_thread.py", line 33, in run_sync
    return await get_asynclib().run_sync_in_worker_thread(
  File "/usr/local/lib/python3.10/dist-packages/anyio/_backends/_asyncio.py", line 877, in run_sync_in_worker_thread
    return await future
  File "/usr/local/lib/python3.10/dist-packages/anyio/_backends/_asyncio.py", line 807, in run
    result = context.run(func, *args)
  File "/root/KHT_Team/Src/api_provider2.py", line 27, in pull_static_data
    geojson_data = postgreSQL.get_table("village")
  File "/root/KHT_Team/Src/postgreSQL.py", line 42, in get_table
    geojson_result = query_to_geojson(cursor, query)
  File "/root/KHT_Team/Src/postgreSQL.py", line 31, in query_to_geojson
    feature = geojson.Feature(geometry=geometry, properties=properties)
  File "/usr/local/lib/python3.10/dist-packages/geojson/feature.py", line 24, in __init__
    self["geometry"] = (self.to_instance(geometry, strict=True)
  File "/usr/local/lib/python3.10/dist-packages/geojson/base.py", line 113, in to_instance
    instance = geojson_factory(**d)
  File "/usr/local/lib/python3.10/dist-packages/geojson/geometry.py", line 29, in __init__
    self["coordinates"] = self.clean_coordinates(
  File "/usr/local/lib/python3.10/dist-packages/geojson/geometry.py", line 53, in clean_coordinates
    raise ValueError("%r is not a JSON compliant number" % coord)
ValueError: None is not a JSON compliant number
INFO:     Shutting down
INFO:     Waiting for application shutdown.
INFO:     Application shutdown complete.
INFO:     Finished server process [25245]
